Workbook

Sheet Data Entry
A1: Personal Wellbeing Index — Client Outcome Tracker
A2: Intake # | B2: Client Name | C2: Cohort / Program | D2: Life Overall | G2: Standard of Living | J2: Health | M2: Achieving in Life | P2: Personal Relationships | S2: Safety | V2: Community | Y2: Future Security | AB2: Financial Worry | AE2: Self-Confidence | AH2: Voice & Agency | AK2: Work Readiness | AN2: Career Confidence | AQ2: Skills Awareness
D3: Baseline | E3: 3 Months | F3: 6 Months | G3: Baseline | H3: 3 Months | I3: 6 Months | J3: Baseline | K3: 3 Months | L3: 6 Months | M3: Baseline | N3: 3 Months | O3: 6 Months | P3: Baseline | Q3: 3 Months | R3: 6 Months | S3: Baseline | T3: 3 Months | U3: 6 Months | V3: Baseline | W3: 3 Months | X3: 6 Months | Y3: Baseline | Z3: 3 Months | AA3: 6 Months | AB3: Baseline | AC3: 3 Months | AD3: 6 Months | AE3: Baseline | AF3: 3 Months | AG3: 6 Months | AH3: Baseline | AI3: 3 Months | AJ3: 6 Months | AK3: Baseline | AL3: 3 Months | AM3: 6 Months | AN3: Baseline | AO3: 3 Months | AP3: 6 Months | AQ3: Baseline | AR3: 3 Months | AS3: 6 Months
A4: ↓ Scale / Response Key | D4: 0–10 | G4: 0–10 | J4: 0–10 | M4: 0–10 | P4: 0–10 | S4: 0–10 | V4: 0–10 | Y4: 0–10 | AB4: 1=Great deal 2=Great extent 3=A little 4=Don't worry 5=Don't know | AE4: 1=Shame/embarrassed → 5=Confident in myself | AH4: 1=No voice, nobody listens → 5=Can speak out, people listen | AK4: 1=Strongly disagree → 5=Strongly agree | AN4: 0–10 | AQ4: 0–10
A5: ↓ Full Question | D5: How satisfied are you with your life as a whole? | G5: How satisfied are you with your standard of living? | J5: How satisfied are you with your health? | M5: How satisfied are you with what you are achieving in life? | P5: How satisfied are you with your personal relationships? | S5: How satisfied are you with how safe you feel? | V5: How satisfied are you with feeling part of your community? | Y5: How satisfied are you with your future security? | AB5: To what extent, if at all, do you worry about your financial situation? | AE5: How do you usually feel about yourself? (Shame → Confidence) | AH5: How do you usually feel about expressing yourself? | AK5: I feel ready and willing to work | AN5: Feeling Work-Ready: Confidence in Career Options — On a scale of 1–10, how confident do you feel about the career paths available to you? | AQ5: Feeling Work-Ready: Understanding Your Skills — On a scale of 1–10, how well do you understand how your skills can be applied to future jobs or training opportunities?
A6: 23 | B6: Sherrybe Raymundo | C6: WWE | D6: 2 | E6: 7 | F6: 8 | G6: 4 | H6: 7 | I6: 8 | J6: 1 | K6: 7 | L6: 8 | M6: 1 | N6: 8 | O6: 9 | P6: 2 | Q6: 8 | R6: 9 | S6: 2 | T6: 8 | U6: 8 | V6: 4 | W6: 8 | X6: 9 | Y6: 1 | Z6: 6 | AA6: 8 | AB6: 1 | AC6: 3 | AD6: 3 | AE6: 2 | AF6: 4 | AG6: 4 | AH6: 3 | AI6: 4 | AJ6: 4 | AK6: 2 | AL6: 5 | AM6: 5
A7: 23 | B7: Joelene Sara | C7: WWE | D7: 3 | E7: 6 | F7: 8 | G7: 3 | H7: 7 | I7: 8 | J7: 3 | K7: 5 | L7: 8 | M7: 2 | N7: 6 | O7: 9 | P7: 2 | Q7: 6 | R7: 9 | S7: 3 | T7: 7 | U7: 8 | V7: 2 | W7: 6 | X7: 9 | Y7: 2 | Z7: 6 | AA7: 8 | AB7: 1 | AC7: 2 | AD7: 3 | AE7: 1 | AF7: 3 | AG7: 4 | AH7: 1 | AI7: 3 | AJ7: 4 | AK7: 1 | AL7: 3 | AM7: 5 | AN7: 2 | AO7: 5 | AP7: 7 | AQ7: 2 | AR7: 5 | AS7: 6
A8: 23 | B8: Roshini McKay | C8: WWE | D8: 1 | E8: 8 | F8: 8 | G8: 1 | H8: 8 | I8: 7 | J8: 1 | K8: 7 | L8: 7 | M8: 1 | N8: 9 | O8: 8 | P8: 1 | Q8: 9 | R8: 10 | S8: 1 | T8: 9 | U8: 4 | V8: 1 | W8: 7 | X8: 10 | Y8: 1 | Z8: 8 | AA8: 10 | AB8: 1 | AC8: 3 | AD8: 4 | AE8: 1 | AF8: 5 | AG8: 4 | AH8: 1 | AI8: 4 | AJ8: 4 | AK8: 1 | AL8: 4 | AM8: 5 | AN8: 3 | AO8: 5 | AP8: 10 | AQ8: 3 | AR8: 5 | AS8: 10
A9: 23 | B9: Ann Marie Miskos | C9: WWE | D9: 3 | E9: 7 | F9: 8 | G9: 4 | H9: 8 | I9: 7 | J9: 2 | K9: 6 | L9: 4 | M9: 4 | N9: 8 | O9: 8 | P9: 2 | Q9: 8 | R9: 8 | S9: 4 | T9: 9 | U9: 9 | V9: 1 | W9: 7 | X9: 8 | Y9: 3 | Z9: 8 | AA9: 7 | AB9: 1 | AC9: 3 | AD9: 1 | AE9: 1 | AF9: 2 | AG9: 3 | AH9: 2 | AI9: 4 | AJ9: 4 | AK9: 2 | AL9: 3 | AM9: 4 | AN9: 3 | AO9: 6 | AP9: 9 | AQ9: 6 | AR9: 8 | AS9: 8
A10: 23 | B10: Marsha Gatt | C10: WWE | D10: 1 | E10: 8 | F10: 9 | G10: 2 | H10: 7 | I10: 10 | J10: 2 | K10: 8 | L10: 9 | M10: 1 | N10: 7 | O10: 10 | P10: 1 | Q10: 9 | R10: 10 | S10: 1 | T10: 1 | U10: 10 | V10: 1 | W10: 7 | X10: 8 | Y10: 1 | Z10: 6 | AA10: 9 | AB10: 1 | AC10: 3 | AD10: 3 | AE10: 1 | AF10: 3 | AG10: 5 | AH10: 1 | AI10: 3 | AJ10: 4 | AK10: 1 | AL10: 3 | AM10: 5 | AN10: 5 | AO10: 8 | AP10: 8 | AQ10: 5 | AR10: 9 | AS10: 9
A11: 23 | B11: Jianing Qin | C11: WWE | D11: 5 | E11: 7 | F11: 8 | G11: 5 | H11: 7 | I11: 9 | J11: 4 | K11: 7 | L11: 8 | M11: 3 | N11: 7 | O11: 8 | P11: 3 | Q11: 7 | R11: 8 | S11: 3 | T11: 8 | U11: 8 | V11: 2 | W11: 8 | X11: 8 | Y11: 2 | Z11: 9 | AA11: 9 | AB11: 2 | AC11: 4 | AD11: 5 | AE11: 1 | AF11: 3 | AG11: 4 | AH11: 2 | AI11: 4 | AJ11: 4 | AK11: 3 | AL11: 3 | AM11: 5 | AN11: 4 | AO11: 7 | AP11: 9 | AQ11: 5 | AR11: 7 | AS11: 10
A12: 24 | B12: Ashlee Sciortino | C12: WWE | D12: 4 | E12: 7 | F12: 9 | G12: 2 | H12: 5 | I12: 8 | J12: 3 | K12: 6 | L12: 7 | M12: 2 | N12: 7 | O12: 9 | P12: 5 | Q12: 6 | R12: 8 | S12: 2 | T12: 5 | U12: 7 | V12: 3 | W12: 5 | X12: 9 | Y12: 2 | Z12: 5 | AA12: 9 | AB12: 1 | AC12: 2 | AD12: 3 | AE12: 1 | AF12: 2 | AG12: 3 | AH12: 2 | AI12: 4 | AJ12: 5 | AK12: 2 | AL12: 4 | AM12: 4 | AN12: 3 | AO12: 7 | AP12: 9 | AQ12: 7 | AR12: 7 | AS12: 9
A13: 24 | B13: Samira Sun | C13: WWE | D13: 5 | E13: 6 | F13: 6 | G13: 5 | H13: 6 | I13: 6 | J13: 3 | K13: 4 | L13: 4 | M13: 2 | N13: 7 | O13: 8 | P13: 4 | Q13: 3 | R13: 5 | S13: 4 | T13: 6 | U13: 6 | V13: 3 | W13: 6 | X13: 6 | Y13: 2 | Z13: 5 | AA13: 5 | AB13: 1 | AC13: 1 | AD13: 3 | AE13: 1 | AF13: 3 | AG13: 4 | AH13: 3 | AI13: 4 | AJ13: 4 | AK13: 1 | AL13: 4 | AM13: 5 | AN13: 6 | AO13: 5 | AP13: 8 | AQ13: 6 | AR13: 5 | AS13: 8
A14: 24 | B14: Sarah Sharpe | C14: WWE | D14: 2 | E14: 6 | G14: 2 | H14: 7 | J14: 3 | K14: 6 | M14: 2 | N14: 7 | P14: 3 | Q14: 6 | S14: 3 | T14: 9 | V14: 2 | W14: 5 | Y14: 2 | Z14: 6 | AB14: 1 | AC14: 2 | AE14: 1 | AF14: 2 | AH14: 2 | AI14: 4 | AK14: 1 | AL14: 2 | AN14: 3 | AO14: 5 | AP14: 5 | AQ14: 5 | AR14: 5 | AS14: 6
A15: 24 | B15: Tiahna Wilson | C15: WWE | D15: 5 | E15: 7 | F15: 8 | G15: 5 | H15: 9 | I15: 10 | J15: 4 | K15: 9 | L15: 9 | M15: 4 | N15: 9 | O15: 9 | P15: 6 | Q15: 9 | R15: 9 | S15: 10 | T15: 7 | U15: 10 | V15: 9 | W15: 8 | X15: 10 | Y15: 3 | Z15: 7 | AA15: 9 | AB15: 2 | AC15: 3 | AD15: 4 | AE15: 2 | AF15: 5 | AG15: 5 | AH15: 4 | AI15: 5 | AJ15: 5 | AK15: 2 | AL15: 5 | AM15: 5 | AN15: 10 | AO15: 9 | AP15: 10 | AQ15: 9 | AR15: 10 | AS15: 10
A16: 24 | B16: Carli Tahane | C16: WWE | D16: 6 | E16: 7 | F16: 8 | G16: 6 | H16: 8 | I16: 9 | J16: 5 | K16: 7 | L16: 9 | M16: 6 | N16: 8 | O16: 10 | P16: 5 | Q16: 8 | R16: 9 | S16: 5 | T16: 8 | U16: 9 | V16: 4 | W16: 8 | X16: 9 | Y16: 4 | Z16: 8 | AA16: 9 | AB16: 1 | AC16: 3 | AD16: 3 | AE16: 2 | AF16: 4 | AG16: 4 | AH16: 2 | AI16: 4 | AJ16: 4 | AK16: 2 | AL16: 4 | AM16: 5 | AN16: 3 | AO16: 8 | AP16: - | AQ16: 5 | AR16: 8 | AS16: -
A17: 24 | B17: Rachel Cowie | C17: WWE | D17: 1 | E17: 7 | F17: 9 | G17: 3 | H17: 8 | I17: 8 | J17: 2 | K17: 7 | L17: 9 | M17: 3 | N17: 8 | O17: 8 | P17: 2 | Q17: 7 | R17: 7 | S17: 1 | T17: 9 | U17: 10 | V17: 1 | W17: 5 | X17: 5 | Y17: 2 | Z17: 8 | AA17: 9 | AB17: 1 | AC17: 3 | AD17: 2 | AE17: 2 | AF17: 4 | AG17: 4 | AH17: 2 | AI17: 3 | AJ17: 3 | AK17: 2 | AL17: 3 | AM17: 4 | AN17: 3 | AO17: 7 | AP17: 10 | AQ17: 3 | AR17: 8 | AS17: 9
A18: 24 | B18: Vaidehi Kumar | C18: WWE | D18: 1 | E18: 6 | F18: 10 | G18: 3 | H18: 8 | I18: 10 | J18: 5 | K18: 5 | L18: 8 | M18: 1 | N18: 8 | O18: 10 | P18: 6 | Q18: 8 | R18: 9 | S18: 1 | T18: 9 | U18: 10 | V18: 1 | W18: 7 | X18: 10 | Y18: 1 | Z18: 7 | AA18: 10 | AB18: 1 | AC18: 3 | AD18: 4 | AE18: 2 | AF18: 1 | AG18: 5 | AH18: 1 | AI18: 2 | AJ18: 5 | AK18: 1 | AL18: 3 | AM18: 5 | AN18: 4 | AO18: 6 | AP18: 10 | AQ18: 5 | AR18: 6 | AS18: 10
A19: 25 | B19: Farzana Sultana | C19: WWE | D19: 2 | E19: 4 | F19: 9 | G19: 2 | H19: 8 | I19: 9 | J19: 7 | K19: 4 | L19: 2 | M19: 3 | N19: 8 | O19: 8 | P19: 4 | Q19: 5 | R19: 10 | S19: 1 | T19: 8 | U19: 9 | V19: 9 | W19: 7 | X19: 7 | Y19: 1 | Z19: 5 | AA19: 6 | AB19: 1 | AC19: 2 | AD19: 3 | AE19: 4 | AF19: 4 | AG19: 5 | AH19: 3 | AI19: 5 | AJ19: 5 | AK19: 5 | AL19: 5 | AM19: 5 | AN19: 6 | AO19: 8 | AP19: 9 | AQ19: 6 | AR19: 8 | AS19: 9
A20: 25 | B20: Rose Nakisanze | C20: WWE | D20: 4 | E20: 7 | F20: 9 | G20: 3 | H20: 7 | I20: 9 | J20: 5 | K20: 9 | L20: 9 | M20: 1 | N20: 7 | O20: 9 | P20: 5 | Q20: 6 | R20: 8 | S20: 7 | T20: 8 | U20: 9 | V20: 2 | W20: 8 | X20: 8 | Y20: 1 | Z20: 7 | AA20: 9 | AB20: 1 | AC20: 3 | AD20: 4 | AE20: 3 | AF20: 4 | AG20: 4 | AH20: 3 | AI20: 5 | AJ20: 4 | AK20: 5 | AL20: 5 | AM20: 4 | AN20: 5 | AO20: 8 | AP20: 8 | AQ20: 6 | AR20: 8 | AS20: 8
A21: 25 | B21: Stephanie Abbott | C21: WWE | D21: 6 | E21: 6 | F21: 8 | G21: 5 | H21: 6 | I21: 9 | J21: 6 | K21: 6 | L21: 7 | M21: 5 | N21: 7 | O21: 9 | P21: 5 | Q21: 6 | R21: 9 | S21: 6 | T21: 6 | U21: 9 | V21: 6 | W21: 7 | X21: 8 | Y21: 5 | Z21: 7 | AA21: 9 | AB21: 1 | AC21: 3 | AD21: 4 | AE21: 2 | AF21: 3 | AG21: 4 | AH21: 3 | AI21: 4 | AJ21: 3 | AK21: 2 | AL21: 5 | AM21: 5 | AN21: 5 | AO21: 7 | AP21: 8 | AQ21: 5 | AR21: 8 | AS21: 9
A22: 25 | B22: Salome Sulu | C22: WWE | D22: 2 | E22: 4 | F22: 8 | G22: 2 | H22: 7 | I22: 9 | J22: 7 | K22: 9 | L22: 10 | M22: 2 | N22: 9 | O22: 9 | P22: 1 | Q22: 9 | R22: 10 | S22: 6 | T22: 8 | U22: 8 | V22: 1 | W22: 9 | X22: 9 | Y22: 2 | Z22: 8 | AA22: 9 | AB22: 1 | AC22: 2 | AD22: 3 | AE22: 1 | AF22: 2 | AG22: 4 | AH22: 1 | AI22: 3 | AJ22: 4 | AK22: 2 | AL22: 4 | AM22: 5 | AN22: 4 | AO22: 8 | AP22: 9 | AQ22: 4 | AR22: 8 | AS22: 9
A23: 25 | B23: Joy Choi | C23: WWE | D23: 3 | E23: 4 | F23: 6 | G23: 3 | H23: 7 | I23: 9 | J23: 5 | K23: 5 | L23: 7 | M23: 7 | N23: 7 | O23: 9 | P23: 1 | Q23: 2 | R23: 5 | S23: 7 | T23: 4 | U23: 5 | V23: 1 | W23: 4 | X23: 5 | Y23: 2 | Z23: 3 | AA23: 5 | AB23: 2 | AC23: 3 | AD23: 4 | AE23: 1 | AF23: 2 | AG23: 3 | AH23: 1 | AI23: 2 | AJ23: 2 | AK23: 2 | AL23: 5 | AM23: 5 | AN23: 5 | AO23: 5 | AP23: 7 | AQ23: 3 | AR23: 5 | AS23: 7
A24: 25 | B24: Iweta Davis | C24: WWE | D24: 3 | E24: 8 | F24: 8 | G24: 4 | H24: 7 | I24: 6 | J24: 7 | K24: 7 | L24: 8 | M24: 5 | N24: 6 | O24: 7 | P24: 5 | Q24: 6 | R24: 8 | S24: 6 | T24: 7 | U24: 8 | V24: 3 | W24: 5 | X24: 7 | Y24: 1 | Z24: 7 | AA24: 6 | AB24: 2 | AC24: 3 | AD24: 3 | AE24: 3 | AF24: 3 | AG24: 4 | AH24: 3 | AI24: 3 | AJ24: 5 | AK24: 3 | AL24: 3 | AM24: 4 | AN24: 5 | AO24: 6 | AP24: 8 | AQ24: 5 | AR24: 6 | AS24: 8
A25: 25 | B25: Kathy Te Nuku | C25: WWE | D25: 2 | E25: 5 | F25: 8 | G25: 1 | H25: 9 | I25: 9 | J25: 7 | K25: 2 | L25: 8 | M25: 2 | N25: 9 | O25: 9 | P25: 3 | Q25: 9 | R25: 9 | S25: 9 | T25: 8 | U25: 10 | V25: 2 | W25: 7 | X25: 9 | Y25: 1 | Z25: 6 | AA25: 9 | AB25: 1 | AC25: 3 | AD25: 9 | AE25: 2 | AF25: 5 | AG25: 3 | AH25: 4 | AI25: 5 | AJ25: 5 | AK25: 5 | AL25: 5 | AM25: 5 | AN25: 3 | AO25: 8 | AP25: - | AQ25: 3 | AR25: 8 | AS25: -
A26: 26 | B26: Shinta Dwihartianti | C26: WWE | D26: 2 | E26: 7 | G26: 2 | H26: 8 | J26: 9 | K26: 7 | M26: 3 | N26: 8 | P26: 5 | Q26: 9 | S26: 7 | T26: 8 | V26: 3 | W26: 7 | Y26: 1 | Z26: 9 | AB26: 2 | AC26: 4 | AE26: 3 | AF26: 5 | AH26: 3 | AI26: 3 | AK26: 2 | AL26: 3 | AN26: 4 | AO26: 8 | AQ26: 4 | AR26: 8
A27: 26 | B27: Carlie Soussa | C27: WWE | D27: 3 | E27: 7 | G27: 2 | H27: 6 | J27: 6 | K27: 8 | M27: 6 | N27: 8 | P27: 3 | Q27: 7 | S27: 9 | T27: 9 | V27: 5 | W27: 8 | Y27: 2 | Z27: 7 | AB27: 2 | AC27: 2 | AE27: 1 | AF27: 2 | AH27: 2 | AI27: 3 | AK27: 2 | AL27: 4 | AN27: 4 | AO27: 7 | AQ27: 4 | AR27: 7
A28: 26 | B28: Claire Thew | C28: WWE | D28: 5 | E28: 7 | G28: 4 | H28: 8 | J28: 4 | K28: 6 | M28: 5 | N28: 7 | P28: 6 | Q28: 9 | S28: 4 | T28: 7 | V28: 4 | W28: 8 | Y28: 3 | Z28: 7 | AB28: 2 | AC28: 3 | AE28: 3 | AF28: 3 | AH28: 4 | AI28: 4 | AK28: 2 | AL28: 4 | AN28: 5 | AO28: 7 | AQ28: 5 | AR28: 8
A29: 26 | B29: Julia Lane | C29: WWE | D29: 6 | E29: 8 | G29: 5 | H29: 7 | J29: 4 | K29: 7 | M29: 5 | N29: 6 | P29: 6 | Q29: 8 | S29: 5 | T29: 9 | V29: 6 | W29: 8 | Y29: 3 | Z29: 7 | AB29: 2 | AC29: 3 | AE29: 3 | AF29: 3 | AH29: 4 | AI29: 4 | AK29: 2 | AL29: 4 | AN29: 4 | AO29: 7 | AQ29: 4 | AR29: 7
A30: 26 | B30: Kaysha Fountain | C30: WWE | D30: 4 | E30: 8 | G30: 6 | H30: 8 | J30: 6 | K30: 7 | M30: 2 | N30: 7 | P30: 5 | Q30: 8 | S30: 8 | T30: 9 | V30: 4 | W30: 6 | Y30: 2 | Z30: 4 | AB30: 1 | AC30: 1 | AE30: 3 | AF30: 3 | AH30: 5 | AI30: 4 | AK30: 2 | AL30: 4 | AN30: 3 | AO30: 8 | AQ30: 4 | AR30: 7
A31: 26 | B31: Lesley Loxley | C31: WWE | D31: 2 | E31: 7 | G31: 4 | H31: 5 | J31: 3 | K31: 4 | M31: 2 | N31: 6 | P31: 4 | Q31: 7 | S31: 3 | T31: 8 | V31: 3 | W31: 7 | Y31: 2 | Z31: 6 | AB31: 1 | AC31: 2 | AE31: 2 | AF31: 2 | AH31: 2 | AI31: 4 | AK31: 2 | AL31: 4 | AN31: 5 | AO31: 6 | AQ31: 5 | AR31: 6
A32: 26 | B32: Lilmani Chaudhary | C32: WWE | D32: 5 | E32: 7 | G32: 4 | H32: 7 | J32: 4 | K32: 3 | M32: 7 | N32: 5 | P32: 7 | Q32: 6 | S32: 10 | T32: 10 | V32: 4 | W32: 6 | Y32: 4 | Z32: 6 | AB32: 1 | AC32: 1 | AE32: 3 | AF32: 2 | AH32: 3 | AI32: 3 | AK32: 3 | AL32: 4 | AN32: 4 | AO32: 10 | AQ32: 4 | AR32: 10
A33: 26 | B33: Nirmala Nadia | C33: WWE | D33: 4 | E33: 7 | G33: 4 | H33: 7 | J33: 7 | K33: 7 | M33: 5 | N33: 7 | P33: 7 | Q33: 8 | S33: 4 | T33: 8 | V33: 6 | W33: 8 | Y33: 2 | Z33: 6 | AB33: 1 | AC33: 3 | AE33: 3 | AF33: 4 | AH33: 4 | AI33: 4 | AK33: 3 | AL33: 5 | AN33: 4 | AO33: 8 | AQ33: 4 | AR33: 8
A34: 26 | B34: Sally Rooke | C34: WWE | D34: 3 | E34: 5 | G34: 2 | H34: 5 | J34: 4 | K34: 5 | M34: 2 | N34: 6 | P34: 5 | Q34: 6 | S34: 9 | T34: 10 | V34: 2 | W34: 6 | Y34: 1 | Z34: 5 | AB34: 1 | AC34: 2 | AE34: 2 | AF34: 3 | AH34: 2 | AI34: 2 | AK34: 4 | AL34: 3 | AN34: 4 | AO34: 6 | AQ34: 4 | AR34: 5

Sheet Summary
A1: PWI Summary — Average Scores by Time Point
A2: Question / Domain | B2: Full Question | C2: Scale | D2: Avg — Baseline | E2: Avg — 3 Months | F2: Avg — 6 Months | G2: Change (B→3mo) | H2: Change (B→6mo)
A3: Averages below are calculated from the Data Entry sheet (rows 6–55). Blank cells are excluded. Add more rows on Data Entry as needed and update formulas.
A4: Life Overall | B4: How satisfied are you with your life as a whole? | C4: 0–10 | D4: =IFERROR(AVERAGEIF('Data Entry'!D6:D55,"<>",'Data Entry'!D6:D55),"–") -> 3.2758621 | E4: =IFERROR(AVERAGEIF('Data Entry'!E6:E55,"<>",'Data Entry'!E6:E55),"–") -> 6.5517241 | F4: =IFERROR(AVERAGEIF('Data Entry'!F6:F55,"<>",'Data Entry'!F6:F55),"–") -> 8.1578947 | G4: =IFERROR(E4-D4,"–") -> 3.2758621 | H4: =IFERROR(F4-D4,"–") -> 4.8820327
A5: Standard of Living | B5: How satisfied are you with your standard of living? | C5: 0–10 | D5: =IFERROR(AVERAGEIF('Data Entry'!G6:G55,"<>",'Data Entry'!G6:G55),"–") -> 3.3793103 | E5: =IFERROR(AVERAGEIF('Data Entry'!H6:H55,"<>",'Data Entry'!H6:H55),"–") -> 7.137931 | F5: =IFERROR(AVERAGEIF('Data Entry'!I6:I55,"<>",'Data Entry'!I6:I55),"–") -> 8.4210526 | G5: =IFERROR(E5-D5,"–") -> 3.7586207 | H5: =IFERROR(F5-D5,"–") -> 5.0417423
A6: Health | B6: How satisfied are you with your health? | C6: 0–10 | D6: =IFERROR(AVERAGEIF('Data Entry'!J6:J55,"<>",'Data Entry'!J6:J55),"–") -> 4.4482759 | E6: =IFERROR(AVERAGEIF('Data Entry'!K6:K55,"<>",'Data Entry'!K6:K55),"–") -> 6.2068966 | F6: =IFERROR(AVERAGEIF('Data Entry'!L6:L55,"<>",'Data Entry'!L6:L55),"–") -> 7.4210526 | G6: =IFERROR(E6-D6,"–") -> 1.7586207 | H6: =IFERROR(F6-D6,"–") -> 2.9727768
A7: Achieving in Life | B7: How satisfied are you with what you are achieving in life? | C7: 0–10 | D7: =IFERROR(AVERAGEIF('Data Entry'!M6:M55,"<>",'Data Entry'!M6:M55),"–") -> 3.2413793 | E7: =IFERROR(AVERAGEIF('Data Entry'!N6:N55,"<>",'Data Entry'!N6:N55),"–") -> 7.3103448 | F7: =IFERROR(AVERAGEIF('Data Entry'!O6:O55,"<>",'Data Entry'!O6:O55),"–") -> 8.7368421 | G7: =IFERROR(E7-D7,"–") -> 4.0689655 | H7: =IFERROR(F7-D7,"–") -> 5.4954628
A8: Personal Relationships | B8: How satisfied are you with your personal relationships? | C8: 0–10 | D8: =IFERROR(AVERAGEIF('Data Entry'!P6:P55,"<>",'Data Entry'!P6:P55),"–") -> 3.9310345 | E8: =IFERROR(AVERAGEIF('Data Entry'!Q6:Q55,"<>",'Data Entry'!Q6:Q55),"–") -> 7.0689655 | F8: =IFERROR(AVERAGEIF('Data Entry'!R6:R55,"<>",'Data Entry'!R6:R55),"–") -> 8.4210526 | G8: =IFERROR(E8-D8,"–") -> 3.137931 | H8: =IFERROR(F8-D8,"–") -> 4.4900181
A9: Safety | B9: How satisfied are you with how safe you feel? | C9: 0–10 | D9: =IFERROR(AVERAGEIF('Data Entry'!S6:S55,"<>",'Data Entry'!S6:S55),"–") -> 4.862069 | E9: =IFERROR(AVERAGEIF('Data Entry'!T6:T55,"<>",'Data Entry'!T6:T55),"–") -> 7.6551724 | F9: =IFERROR(AVERAGEIF('Data Entry'!U6:U55,"<>",'Data Entry'!U6:U55),"–") -> 8.2631579 | G9: =IFERROR(E9-D9,"–") -> 2.7931034 | H9: =IFERROR(F9-D9,"–") -> 3.4010889
A10: Community | B10: How satisfied are you with feeling part of your community? | C10: 0–10 | D10: =IFERROR(AVERAGEIF('Data Entry'!V6:V55,"<>",'Data Entry'!V6:V55),"–") -> 3.2758621 | E10: =IFERROR(AVERAGEIF('Data Entry'!W6:W55,"<>",'Data Entry'!W6:W55),"–") -> 6.8275862 | F10: =IFERROR(AVERAGEIF('Data Entry'!X6:X55,"<>",'Data Entry'!X6:X55),"–") -> 8.1052632 | G10: =IFERROR(E10-D10,"–") -> 3.5517241 | H10: =IFERROR(F10-D10,"–") -> 4.8294011
A11: Future Security | B11: How satisfied are you with your future security? | C11: 0–10 | D11: =IFERROR(AVERAGEIF('Data Entry'!Y6:Y55,"<>",'Data Entry'!Y6:Y55),"–") -> 2.0344828 | E11: =IFERROR(AVERAGEIF('Data Entry'!Z6:Z55,"<>",'Data Entry'!Z6:Z55),"–") -> 6.5172414 | F11: =IFERROR(AVERAGEIF('Data Entry'!AA6:AA55,"<>",'Data Entry'!AA6:AA55),"–") -> 8.1578947 | G11: =IFERROR(E11-D11,"–") -> 4.4827586 | H11: =IFERROR(F11-D11,"–") -> 6.123412
A12: Financial Worry | B12: To what extent, if at all, do you worry about your financial situation? | C12: 1=Great deal 2=Great extent 3=A little 4=Don't worry 5=Don't know | D12: =IFERROR(AVERAGEIF('Data Entry'!AB6:AB55,"<>",'Data Entry'!AB6:AB55),"–") -> 1.2758621 | E12: =IFERROR(AVERAGEIF('Data Entry'!AC6:AC55,"<>",'Data Entry'!AC6:AC55),"–") -> 2.5862069 | F12: =IFERROR(AVERAGEIF('Data Entry'!AD6:AD55,"<>",'Data Entry'!AD6:AD55),"–") -> 3.5789474 | G12: =IFERROR(E12-D12,"–") -> 1.3103448 | H12: =IFERROR(F12-D12,"–") -> 2.3030853
A13: Self-Confidence | B13: How do you usually feel about yourself? (Shame → Confidence) | C13: 1=Shame/embarrassed → 5=Confident in myself | D13: =IFERROR(AVERAGEIF('Data Entry'!AE6:AE55,"<>",'Data Entry'!AE6:AE55),"–") -> 1.9655172 | E13: =IFERROR(AVERAGEIF('Data Entry'!AF6:AF55,"<>",'Data Entry'!AF6:AF55),"–") -> 3.137931 | F13: =IFERROR(AVERAGEIF('Data Entry'!AG6:AG55,"<>",'Data Entry'!AG6:AG55),"–") -> 4 | G13: =IFERROR(E13-D13,"–") -> 1.1724138 | H13: =IFERROR(F13-D13,"–") -> 2.0344828
A14: Voice & Agency | B14: How do you usually feel about expressing yourself? | C14: 1=No voice, nobody listens → 5=Can speak out, people listen | D14: =IFERROR(AVERAGEIF('Data Entry'!AH6:AH55,"<>",'Data Entry'!AH6:AH55),"–") -> 2.5172414 | E14: =IFERROR(AVERAGEIF('Data Entry'!AI6:AI55,"<>",'Data Entry'!AI6:AI55),"–") -> 3.6551724 | F14: =IFERROR(AVERAGEIF('Data Entry'!AJ6:AJ55,"<>",'Data Entry'!AJ6:AJ55),"–") -> 4.1052632 | G14: =IFERROR(E14-D14,"–") -> 1.137931 | H14: =IFERROR(F14-D14,"–") -> 1.5880218
A15: Work Readiness | B15: I feel ready and willing to work | C15: 1=Strongly disagree → 5=Strongly agree | D15: =IFERROR(AVERAGEIF('Data Entry'!AK6:AK55,"<>",'Data Entry'!AK6:AK55),"–") -> 2.3103448 | E15: =IFERROR(AVERAGEIF('Data Entry'!AL6:AL55,"<>",'Data Entry'!AL6:AL55),"–") -> 3.8965517 | F15: =IFERROR(AVERAGEIF('Data Entry'!AM6:AM55,"<>",'Data Entry'!AM6:AM55),"–") -> 4.7368421 | G15: =IFERROR(E15-D15,"–") -> 1.5862069 | H15: =IFERROR(F15-D15,"–") -> 2.4264973
A16: Career Confidence | B16: Feeling Work-Ready: Confidence in Career Options — On a scale of 1–10, how confident do you feel about the career paths available to you? | C16: 0–10 | D16: =IFERROR(AVERAGEIF('Data Entry'!AN6:AN55,"<>",'Data Entry'!AN6:AN55),"–") -> 4.25 | E16: =IFERROR(AVERAGEIF('Data Entry'!AO6:AO55,"<>",'Data Entry'!AO6:AO55),"–") -> 6.9642857 | F16: =IFERROR(AVERAGEIF('Data Entry'!AP6:AP55,"<>",'Data Entry'!AP6:AP55),"–") -> 8.4705882 | G16: =IFERROR(E16-D16,"–") -> 2.7142857 | H16: =IFERROR(F16-D16,"–") -> 4.2205882
A17: Skills Awareness | B17: Feeling Work-Ready: Understanding Your Skills — On a scale of 1–10, how well do you understand how your skills can be applied to future jobs or training opportunities? | C17: 0–10 | D17: =IFERROR(AVERAGEIF('Data Entry'!AQ6:AQ55,"<>",'Data Entry'!AQ6:AQ55),"–") -> 4.6785714 | E17: =IFERROR(AVERAGEIF('Data Entry'!AR6:AR55,"<>",'Data Entry'!AR6:AR55),"–") -> 7.1428571 | F17: =IFERROR(AVERAGEIF('Data Entry'!AS6:AS55,"<>",'Data Entry'!AS6:AS55),"–") -> 8.5294118 | G17: =IFERROR(E17-D17,"–") -> 2.4642857 | H17: =IFERROR(F17-D17,"–") -> 3.8508403

Sheet Guide
A1: How to Use This Tracker
A2: Data Entry sheet | B2: Enter one row per client. Use the Intake # as your unique identifier. Client Name is optional if de-identified data is required.
A3: Cohort / Program | B3: Record the program, service type, or any grouper you need. You can filter/sort this column to view cohorts separately.
A4: Time Points | B4: Enter scores at Baseline (intake), 3 Months, and 6 Months. Leave blank if data is not yet collected — averages on the Summary sheet will still calculate correctly.
A5: PWI Questions (Q1–Q8) | B5: Scored 0–10. 0 = No satisfaction at all. 10 = Completely satisfied.
A6: Financial Worry | B6: Ordinal scale: 1 = Worry a great deal → 4 = Don't worry at all. 5 = Don't know (treat as missing in analysis).
A7: Self-Confidence & Voice | B7: Both use a 1–5 Likert scale. Higher scores = more positive self-perception.
A8: Work Readiness | B8: 1–5 Likert. 1 = Not at all ready → 5 = Fully ready and willing.
A9: Summary sheet | B9: Auto-calculates group averages and change scores. Review these to track cohort-level outcomes over time.
A10: Adding more rows | B10: The Data Entry sheet has 50 rows. To add more, copy the last data row downward. Then update the Summary formulas to extend the range (e.g. change $55 to the new last row).

Sheet Intakes
A1: Intake No | B1: Name | C1: Completed Program | D1: Employment Elsewhere | E1: Darlo | F1: Employment Elsewhere
A2: 23 | B2: Sherrybe Raymundo | C2: 1 | D2: 1 | E2: - | F2: -
A3: 23 | B3: Joelene Sara | C3: 1 | E3: 1 | F3: 1
A4: 23 | B4: Roshini McKay | C4: 1 | D4: 1
A5: 23 | B5: Ann Marie Miskos | C5: 1 | D5: 1
A6: 23 | B6: Marsha Gatt | C6: 1 | D6: 1
A7: 23 | B7: Jessie Clark | C7: -
A8: 23 | B8: Jianing Qin | C8: 1 | E8: 1
A9: 23 | B9: Beata Fu | C9: -
A10: 24 | B10: Ashlee Sciortino | C10: 1 | E10: 1
A11: 24 | B11: Arianna Mulligan | C11: -
A12: 24 | B12: Samira Sun | C12: 1 | D12: 1
A13: 24 | B13: Branda Lee Elliott | C13: -
A14: 24 | B14: Tiahna Wilson | C14: 1 | D14: 1
A15: 24 | B15: Jhassoury Hinostoza | C15: 1 | D15: 1
A16: 24 | B16: Regina Juach | C16: -
A17: 24 | B17: Sarah Sharpe | C17: 1
A18: 24 | B18: Carli Tahane | C18: 1 | D18: 1
A19: 24 | B19: Rachel Cowie | C19: 1
A20: 24 | B20: Vaidehi Kumar | C20: 1 | D20: 1
A21: 25 | B21: Farzana Sultana | C21: 1 | D21: 1
A22: 25 | B22: Rose Nakisanze | C22: 1 | E22: 1
A23: 25 | B23: Angelina Robinson | C23: -
A24: 25 | B24: Kylie Griffiths | C24: -
A25: 25 | B25: Sarah Beta | C25: -
A26: 25 | B26: Melinda McMahon | C26: -
A27: 25 | B27: Stephanie Abbott | C27: 1 | E27: 1
A28: 25 | B28: Salome Sulu | C28: 1
A29: 25 | B29: Joy Choi | C29: 1
A30: 25 | B30: Iweta Davis | C30: 1 | E30: 1 | F30: 1
A31: 25 | B31: Kathy Te Nuku | C31: 1
A32: 26 | B32: Shinta Dwihartianti
A33: 26 | B33: Carlie Soussa
A34: 26 | B34: Claire Thew
A35: 26 | B35: Julia Lane
A36: 26 | B36: Kaysha Fountain
A37: 26 | B37: Lesley Loxley
A38: 26 | B38: Lilmani Chaudhary
A39: 26 | B39: Nirmala Nadia
A40: 26 | B40: Tylah Mace | C40: -
...
